<?xml version="1.0" encoding="utf-8"?><!-- =================================================================================== --><!-- |    This document was autogenerated by xacro from /home/rjgpinel/catkin_ws/src/prl_ur5_robot/prl_ur5_description/urdf/prl_ur5_robot.urdf.xacro | --><!-- |    EDITING THIS FILE BY HAND IS NOT RECOMMENDED                                 | --><!-- =================================================================================== --><robot name="prl_ur5_robot">
  <material name="onrobot/grey">
    <color rgba="0.65 0.62 0.58 1.0"/>
  </material>
  <material name="onrobot/light_grey">
    <color rgba="0.9 0.92 0.93 1.0"/>
  </material>
  <material name="onrobot/dark_grey">
    <color rgba="0.25 0.25 0.25 1.0"/>
  </material>
  <material name="aluminum">
    <color rgba="0.5 0.5 0.5 1"/>
  </material>
  <material name="plastic">
    <color rgba="0.1 0.1 0.1 1"/>
  </material>
  <material name="blue_platinum">
    <color rgba="0.192 0.357 0.451 1"/>
  </material>
  <!-- base link -->
  <link name="prl_ur5_base"><inertial><mass value="0.001"/><inertia ixx="0.00001" ixy="0" ixz="0" iyy="0.00001" iyz="0" izz="0.00001"/></inertial></link>
  <!-- measured from model -->
  <link name="left_base_link">
    <visual>
      <origin rpy="0 0 3.141592653589793" xyz="0 0 0"/>
      <geometry>
        <mesh filename="./meshes/ur5/visual/base.dae"/>
      </geometry>
      <material name="LightGrey">
        <color rgba="0.7 0.7 0.7 1.0"/>
      </material>
    </visual>
    <collision>
      <origin rpy="0 0 3.141592653589793" xyz="0 0 0"/>
      <geometry>
        <mesh filename="./meshes/ur5/collision/base.stl"/>
      </geometry>
    </collision>
    <inertial>
      <mass value="4.0"/>
      <origin rpy="0 0 0" xyz="0.0 0.0 0.0"/>
      <inertia ixx="0.00443333156" ixy="0.0" ixz="0.0" iyy="0.00443333156" iyz="0.0" izz="0.0072"/>
    </inertial>
  </link>
  <joint name="left_shoulder_pan_joint" type="revolute">
    <parent link="left_base_link"/>
    <child link="left_shoulder_link"/>
    <origin rpy="0 0 3.1415899040874247" xyz="0 0 0.08918501667510044"/>
    <axis xyz="0 0 1"/>
    <limit effort="150.0" lower="-3.14159" upper="3.14159" velocity="3.15"/>
    <dynamics damping="0.0" friction="0.0"/>
  </joint>
  <link name="left_shoulder_link">
    <visual>
      <origin rpy="0 0 3.141592653589793" xyz="0 0 0"/>
      <geometry>
        <mesh filename="./meshes/ur5/visual/shoulder.dae"/>
      </geometry>
      <material name="LightGrey">
        <color rgba="0.7 0.7 0.7 1.0"/>
      </material>
    </visual>
    <collision>
      <origin rpy="0 0 3.141592653589793" xyz="0 0 0"/>
      <geometry>
        <mesh filename="./meshes/ur5/collision/shoulder.stl"/>
      </geometry>
    </collision>
    <inertial>
      <mass value="3.7"/>
      <origin rpy="0 0 0" xyz="0.0 0.0 0.0"/>
      <inertia ixx="0.014972352344389999" ixy="0.0" ixz="0.0" iyy="0.014972352344389999" iyz="0.0" izz="0.01040625"/>
    </inertial>
  </link>
  <joint name="left_shoulder_lift_joint" type="revolute">
    <parent link="left_shoulder_link"/>
    <child link="left_upper_arm_link"/>
    <origin rpy="1.570525232048461 0 1.921977645271288e-05" xyz="0.000107269917097091 0 0"/>
    <axis xyz="0 0 1"/>
    <limit effort="150.0" lower="-3.14159" upper="3.14159" velocity="3.15"/>
    <dynamics damping="0.0" friction="0.0"/>
  </joint>
  <link name="left_upper_arm_link">
    <visual>
      <origin rpy="1.5707963267948966 0 -1.5707963267948966" xyz="0 0 0.136"/>
      <geometry>
        <mesh filename="./meshes/ur5/visual/upperarm.dae"/>
      </geometry>
      <material name="LightGrey">
        <color rgba="0.7 0.7 0.7 1.0"/>
      </material>
    </visual>
    <collision>
      <origin rpy="1.5707963267948966 0 -1.5707963267948966" xyz="0 0 0.136"/>
      <geometry>
        <mesh filename="./meshes/ur5/collision/upperarm.stl"/>
      </geometry>
    </collision>
    <inertial>
      <mass value="8.393"/>
      <origin rpy="0 1.5707963267948966 0" xyz="-0.2127477038614434 0.0 0.136"/>
      <inertia ixx="0.13418047535691163" ixy="0.0" ixz="0.0" iyy="0.13418047535691163" iyz="0.0" izz="0.0151074"/>
    </inertial>
  </link>
  <joint name="left_elbow_joint" type="revolute">
    <parent link="left_upper_arm_link"/>
    <child link="left_forearm_link"/>
    <origin rpy="0.000369043097955391 0.0005901088854669997 5.099356470552253e-05" xyz="-0.4254954077228868 0 0"/>
    <axis xyz="0 0 1"/>
    <limit effort="150.0" lower="-3.14159" upper="3.14159" velocity="3.15"/>
    <dynamics damping="0.0" friction="0.0"/>
  </joint>
  <link name="left_forearm_link">
    <visual>
      <origin rpy="1.5707963267948966 0 -1.5707963267948966" xyz="0 0 0.0165"/>
      <geometry>
        <mesh filename="./meshes/ur5/visual/forearm.dae"/>
      </geometry>
      <material name="LightGrey">
        <color rgba="0.7 0.7 0.7 1.0"/>
      </material>
    </visual>
    <collision>
      <origin rpy="1.5707963267948966 0 -1.5707963267948966" xyz="0 0 0.0165"/>
      <geometry>
        <mesh filename="./meshes/ur5/collision/forearm.stl"/>
      </geometry>
    </collision>
    <inertial>
      <mass value="2.275"/>
      <origin rpy="0 1.5707963267948966 0" xyz="-0.2127477038614434 0.0 0.0165"/>
      <inertia ixx="0.03124063802929152" ixy="0.0" ixz="0.0" iyy="0.03124063802929152" iyz="0.0" izz="0.004095"/>
    </inertial>
  </link>
  <joint name="left_wrist_1_joint" type="revolute">
    <parent link="left_forearm_link"/>
    <child link="left_wrist_1_link"/>
    <origin rpy="0.007357465532194211 0.001366817683118754 5.507031446329021e-05" xyz="-0.3924103068549387 -0.0008152208483887941 0.1107998582993478"/>
    <axis xyz="0 0 1"/>
    <limit effort="28.0" lower="-3.14159" upper="3.14159" velocity="3.2"/>
    <dynamics damping="0.0" friction="0.0"/>
  </joint>
  <link name="left_wrist_1_link">
    <visual>
      <origin rpy="1.5707963267948966 0 0" xyz="0 0 -0.093"/>
      <geometry>
        <mesh filename="./meshes/ur5/visual/wrist1.dae"/>
      </geometry>
      <material name="LightGrey">
        <color rgba="0.7 0.7 0.7 1.0"/>
      </material>
    </visual>
    <collision>
      <origin rpy="1.5707963267948966 0 0" xyz="0 0 -0.093"/>
      <geometry>
        <mesh filename="./meshes/ur5/collision/wrist1.stl"/>
      </geometry>
    </collision>
    <inertial>
      <mass value="1.219"/>
      <origin rpy="0 0 0" xyz="0.0 0.0 0.0"/>
      <inertia ixx="0.0026283086923852682" ixy="0.0" ixz="0.0" iyy="0.0026283086923852682" iyz="0.0" izz="0.0034284375"/>
    </inertial>
  </link>
  <joint name="left_wrist_2_joint" type="revolute">
    <parent link="left_wrist_1_link"/>
    <child link="left_wrist_2_link"/>
    <origin rpy="1.569689148919446 0 -3.884674228365137e-06" xyz="1.88989034199928e-05 -0.09486007969995007 0.000105027024422771"/>
    <axis xyz="0 0 1"/>
    <limit effort="28.0" lower="-3.14159" upper="3.14159" velocity="3.2"/>
    <dynamics damping="0.0" friction="0.0"/>
  </joint>
  <link name="left_wrist_2_link">
    <visual>
      <origin rpy="0 0 0" xyz="0 0 -0.095"/>
      <geometry>
        <mesh filename="./meshes/ur5/visual/wrist2.dae"/>
      </geometry>
      <material name="LightGrey">
        <color rgba="0.7 0.7 0.7 1.0"/>
      </material>
    </visual>
    <collision>
      <origin rpy="0 0 0" xyz="0 0 -0.095"/>
      <geometry>
        <mesh filename="./meshes/ur5/collision/wrist2.stl"/>
      </geometry>
    </collision>
    <inertial>
      <mass value="1.219"/>
      <origin rpy="0 0 0" xyz="0.0 0.0 0.0"/>
      <inertia ixx="0.001789107756303019" ixy="0.0" ixz="0.0" iyy="0.001789107756303019" iyz="0.0" izz="0.0021942"/>
    </inertial>
  </link>
  <joint name="left_wrist_3_joint" type="revolute">
    <parent link="left_wrist_2_link"/>
    <child link="left_wrist_3_link"/>
    <origin rpy="1.571563236607506 3.141592653589793 3.141560506388899" xyz="8.727327772039603e-05 0.08253620113769419 6.32978349575522e-05"/>
    <axis xyz="0 0 1"/>
    <limit effort="28.0" lower="-3.14159" upper="3.14159" velocity="3.2"/>
    <dynamics damping="0.0" friction="0.0"/>
  </joint>
  <link name="left_wrist_3_link">
    <visual>
      <origin rpy="1.5707963267948966 0 0" xyz="0 0 -0.0818"/>
      <geometry>
        <mesh filename="./meshes/ur5/visual/wrist3.dae"/>
      </geometry>
      <material name="LightGrey">
        <color rgba="0.7 0.7 0.7 1.0"/>
      </material>
    </visual>
    <collision>
      <origin rpy="1.5707963267948966 0 0" xyz="0 0 -0.0823"/>
      <geometry>
        <mesh filename="./meshes/ur5/collision/wrist3.stl"/>
      </geometry>
    </collision>
    <inertial>
      <mass value="0.1879"/>
      <origin rpy="0 0 0" xyz="0.0 0.0 -0.01525"/>
      <inertia ixx="8.062472608343e-05" ixy="0.0" ixz="0.0" iyy="8.062472608343e-05" iyz="0.0" izz="0.0001321171875"/>
    </inertial>
  </link>
  <joint name="left_ee_fixed_joint" type="fixed">
    <parent link="left_wrist_3_link"/>
    <child link="left_ee_link"/>
    <origin rpy="0.0 -1.5707963267948966 1.5707963267948966" xyz="0.0 0.0 0.0"/>
  </joint>
  <link name="left_ee_link">
    <collision>
      <geometry>
        <box size="0.01 0.01 0.01"/>
      </geometry>
      <origin rpy="0 0 0" xyz="-0.01 0 0"/>
    </collision>
  <inertial><mass value="0.001"/><inertia ixx="0.00001" ixy="0" ixz="0" iyy="0.00001" iyz="0" izz="0.00001"/></inertial></link>
  <joint name="left_wrist_3_passive_joint" type="fixed">
    <origin rpy="0 0 0" xyz="0 0 0"/>
    <parent link="left_wrist_3_link"/>
    <child link="left_tool0"/>
  </joint>
  
  <!-- ROS base_link to UR 'Base' Coordinates transform -->
  <link name="left_base"><inertial><mass value="0.001"/><inertia ixx="0.00001" ixy="0" ixz="0" iyy="0.00001" iyz="0" izz="0.00001"/></inertial></link>
  <joint name="left_base_link-base_fixed_joint" type="fixed">
    <!-- NOTE: this rotation is only needed as long as base_link itself is
                 not corrected wrt the real robot (ie: rotated over 180
                 degrees)
      -->
    <origin rpy="0 0 -3.141592653589793" xyz="0 0 0"/>
    <parent link="left_base_link"/>
    <child link="left_base"/>
  </joint>
  <!-- Frame coincident with all-zeros TCP on UR controller -->
  <link name="left_tool0"><inertial><mass value="0.001"/><inertia ixx="0.00001" ixy="0" ixz="0" iyy="0.00001" iyz="0" izz="0.00001"/></inertial></link>
  <joint name="left_base_joint" type="fixed">
    <origin rpy="0.0 -2.356194490192345 0.0" xyz="-0.17906 -0.3825 0.78936"/>
    <parent link="prl_ur5_base"/>
    <child link="left_base_link"/>
  </joint>
  <!-- mount the fts to the robot -->
  <joint name="left_ft300_fix" type="fixed">
    <origin rpy="0 0 -1.5707963267948966" xyz="0 0 -0.004"/>
    <parent link="left_tool0"/>
    <child link="left_ft300_mounting_plate"/>
  </joint>
  <!-- Link representing the FT300 force-torque sensor -->
  <link name="left_ft300_sensor">
    <inertial>
      <origin rpy="0 0 0" xyz="0 0 -0.017"/>
      <mass value="0.300"/>
      <inertia ixx="0.000262" ixy="0" ixz="1e-06" iyx="0" iyy="0.000265" iyz="1e-06" izx="-1e-06" izy="1e-06" izz="0.000219"/>
    </inertial>
    <visual>
      <origin rpy="0 0 0" xyz="0 0 0"/>
      <geometry>
        <mesh filename="./meshes/robotiq_ft_sensor/visual/robotiq_ft300.STL"/>
      </geometry>
      <material name="Robotiq-Black">
        <color rgba="0.2 0.2 0.2 1.0"/>
      </material>
    </visual>
    <collision>
      <origin rpy="0 0 0" xyz="0 0 0"/>
      <geometry>
        <mesh filename="./meshes/robotiq_ft_sensor/collision/robotiq_ft300.STL"/>
      </geometry>
    </collision>
  </link>
  <!-- Link representing the FT300 mounting plate -->
  <link name="left_ft300_mounting_plate">
    <visual>
      <origin rpy="0 0 0" xyz="0 0 0"/>
      <geometry>
        <mesh filename="./meshes/robotiq_ft_sensor/visual/mountings/robotiq_ft300-G-062-COUPLING_G-50-4M6-1D6_20181119.STL"/>
      </geometry>
      <material name="Robotiq-Grey">
        <color rgba="0.4 0.4 0.4 1.0"/>
      </material>
    </visual>
    <collision>
      <origin rpy="0 0 0" xyz="0 0 0"/>
      <geometry>
        <mesh filename="./meshes/robotiq_ft_sensor/collision/mountings/robotiq_ft300-G-062-COUPLING_G-50-4M6-1D6_20181119.STL"/>
      </geometry>
    </collision>
  <inertial><mass value="0.001"/><inertia ixx="0.00001" ixy="0" ixz="0" iyy="0.00001" iyz="0" izz="0.00001"/></inertial></link>
  <!-- Connect force sensor with mounting/coupling plate -->
  <joint name="left_ft300_mounting_plate" type="fixed">
    <origin rpy="0 3.141592653589793 0" xyz="0 0 0.0415"/>
    <parent link="left_ft300_mounting_plate"/>
    <child link="left_ft300_sensor"/>
  </joint>
  <!-- FORCE REFERENCE FRAME _______________________________________________________________________________
            As specified in the documentation:
            - The Z axis passes through the center of the depression with positive direction in the tool direction.
            - The X axis traces a symmetric line centered on the connector; the positive direction
                points the opposite way away from the connector.
            - The Y axis uses the right hand thumb rule according to X-Z. -->
  <joint name="left_measurment_joint" type="fixed">
    <origin rpy="0 3.141592653589793 -1.5707963267948966" xyz="0 0 0"/>
    <parent link="left_ft300_sensor"/>
    <child link="left_robotiq_ft_frame_id"/>
  </joint>
  <link name="left_robotiq_ft_frame_id"><inertial><mass value="0.001"/><inertia ixx="0.00001" ixy="0" ixz="0" iyy="0.00001" iyz="0" izz="0.00001"/></inertial></link>
   <!-- tool frame -->
  <link name="left_tool"><inertial><mass value="0.001"/><inertia ixx="0.00001" ixy="0" ixz="0" iyy="0.00001" iyz="0" izz="0.00001"/></inertial></link>
  <joint name="left_tool_joint" type="fixed">
    <origin rpy="0 0 0" xyz="0 0 0"/>
    <parent link="left_robotiq_ft_frame_id"/>
    <child link="left_tool"/>
  </joint>
  <!-- bracket -->
  <link name="left_gripper_bracket">
    <visual>
      <geometry>
        <mesh filename="./meshes/rg6_v1/visual/single_bracket.stl"/>
      </geometry>
      <material name="onrobot/grey"/>
    </visual>
    <collision>
      <geometry>
        <mesh filename="./meshes/rg6_v1/collision/single_bracket.stl"/>
      </geometry>
    </collision>
    <inertial>
      <mass value="0.001"/>
      <inertia ixx="0.001" ixy="0.0" ixz="0.0" iyy="0.001" iyz="0.0" izz="0.001"/>
    </inertial>
  </link>
  <joint name="left_gripper_bracket_joint" type="fixed">
    <parent link="left_tool"/>
    <child link="left_gripper_bracket"/>
    <origin rpy="0.0 0.0 0.0" xyz="0.0 0.0 0.0"/>
  </joint>
  <!-- body -->
  <link name="left_gripper_body">
    <visual>
      <geometry>
        <mesh filename="./meshes/rg6_v1/visual/body.stl"/>
      </geometry>
      <material name="onrobot/light_grey"/>
    </visual>
    <collision>
      <geometry>
        <mesh filename="./meshes/rg6_v1/collision/body.stl"/>
      </geometry>
    </collision>
    <inertial>
      <mass value="0.78"/>
      <inertia ixx="0.001" ixy="0.0" ixz="0.0" iyy="0.001" iyz="0.0" izz="0.001"/>
    </inertial>
  </link>
  <joint name="left_gripper_body_joint" type="fixed">
    <parent link="left_gripper_bracket"/>
    <child link="left_gripper_body"/>
    <origin rpy="0.0 0.0 0.0" xyz="0.0 0.0 0.051"/>
  </joint>
  <!-- grasp frame -->
  <link name="left_gripper_grasp_frame"><inertial><mass value="0.001"/><inertia ixx="0.00001" ixy="0" ixz="0" iyy="0.00001" iyz="0" izz="0.00001"/></inertial></link>
  <joint name="left_gripper_grasp_frame_joint" type="fixed">
    <parent link="left_gripper_body"/>
    <child link="left_gripper_grasp_frame"/>
    <origin rpy="0.0 0.0 0.0" xyz="0.0 0.0 0.19"/>
  </joint>
  <!-- origin frame -->
  <link name="left_gripper_finger_1_origin">
    <inertial>
      <mass value="0.001"/>
      <inertia ixx="0.00001" ixy="0.0" ixz="0.0" iyy="0.00001" iyz="0.0" izz="0.00001"/>
    </inertial>
  </link>
  <joint name="left_gripper_finger_1_origin_joint" type="fixed">
    <parent link="left_gripper_body"/>
    <child link="left_gripper_finger_1_origin"/>
    <origin rpy="0 0 0" xyz="0 0 0"/>
  </joint>
  <!-- moment bar -->
  <link name="left_gripper_finger_1_moment_arm">
    <visual>
      <geometry>
        <mesh filename="./meshes/rg6_v1/visual/moment_arm.stl"/>
      </geometry>
      <material name="onrobot/light_grey"/>
    </visual>
    <collision>
      <geometry>
        <mesh filename="./meshes/rg6_v1/collision/moment_arm.stl"/>
      </geometry>
    </collision>
    <inertial>
      <mass value="0.001"/>
      <inertia ixx="0.001" ixy="0.0" ixz="0.0" iyy="0.001" iyz="0.0" izz="0.001"/>
    </inertial>
  </link>
  <joint name="left_gripper_joint" type="revolute">
    <parent link="left_gripper_finger_1_origin"/>
    <child link="left_gripper_finger_1_moment_arm"/>
    <axis xyz="0 1 0"/>
    <origin rpy="0.0 -0.49 0.0" xyz="-0.0238 0.0 0.066"/>
    <limit effort="10.0" lower="0.0" upper="1.3" velocity="2.4"/>
    <dynamics damping="0.5"/>
  </joint>
  <!-- truss bar -->
  <link name="left_gripper_finger_1_truss_arm">
    <visual>
      <geometry>
        <mesh filename="./meshes/rg6_v1/visual/truss_arm.stl"/>
      </geometry>
      <material name="onrobot/light_grey"/>
    </visual>
    <collision>
      <geometry>
        <mesh filename="./meshes/rg6_v1/collision/truss_arm.stl"/>
      </geometry>
    </collision>
    <inertial>
      <mass value="0.001"/>
      <inertia ixx="0.001" ixy="0.0" ixz="0.0" iyy="0.001" iyz="0.0" izz="0.001"/>
    </inertial>
  </link>
  <joint name="left_gripper_finger_1_truss_arm_joint" type="revolute">
    <parent link="left_gripper_finger_1_origin"/>
    <child link="left_gripper_finger_1_truss_arm"/>
    <axis xyz="0 1 0"/>
    <origin rpy="0.0 -0.49 0.0" xyz="-0.0105 0.0 0.0891"/>
    <limit effort="10.0" lower="0.0" upper="1.3" velocity="2.4"/>
    <mimic joint="left_gripper_joint" multiplier="1" offset="0"/>
  </joint>
  <link name="left_gripper_finger_1_safety_shield">
    <visual>
      <geometry>
        <mesh filename="./meshes/rg6_v1/visual/safety_shield.stl"/>
      </geometry>
      <material name="onrobot/dark_grey"/>
    </visual>
    <collision>
      <geometry>
        <!-- <mesh filename="package://onrobot_description/meshes/${model}/collision/safety_shield.stl"/> -->
        <box size="0.0 0.0 0.0"/>
      </geometry>
    </collision>
    <inertial>
      <mass value="0.001"/>
      <inertia ixx="0.001" ixy="0.0" ixz="0.0" iyy="0.001" iyz="0.0" izz="0.001"/>
    </inertial>
  </link>
  <joint name="left_gripper_finger_1_safety_shield_joint" type="revolute">
    <parent link="left_gripper_finger_1_finger_tip"/>
    <child link="left_gripper_finger_1_safety_shield"/>
    <axis xyz="0 1 0"/>
    <origin rpy="0.0 -0.49 0.0" xyz="-0.00665 0.0 -0.01155"/>
    <limit effort="10.0" lower="0.0" upper="1.3" velocity="2.4"/>
    <mimic joint="left_gripper_joint" multiplier="1" offset="0"/>
  </joint>
  <!-- finger tip -->
  <link name="left_gripper_finger_1_finger_tip">
    <visual>
      <geometry>
        <mesh filename="./meshes/rg6_v1/visual/finger_tip.stl"/>
      </geometry>
      <material name="onrobot/light_grey"/>
    </visual>
    <collision>
      <geometry>
        <mesh filename="./meshes/rg6_v1/collision/finger_tip_1.stl"/>
      </geometry>
    </collision>
    <collision>
      <geometry>
        <mesh filename="./meshes/rg6_v1/collision/finger_tip_2.stl"/>
      </geometry>
    </collision>
    <inertial>
      <mass value="0.001"/>
      <inertia ixx="0.001" ixy="0.0" ixz="0.0" iyy="0.001" iyz="0.0" izz="0.001"/>
    </inertial>
  </link>
  <joint name="left_gripper_finger_1_finger_tip_joint" type="revolute">
    <parent link="left_gripper_finger_1_truss_arm"/>
    <child link="left_gripper_finger_1_finger_tip"/>
    <axis xyz="0 -1 0"/>
    <origin rpy="0.0 0.49 0.0" xyz="-0.05503 0.0 0.05807"/>
    <limit effort="10.0" lower="0.0" upper="1.3" velocity="2.4"/>
    <mimic joint="left_gripper_joint" multiplier="1" offset="0"/>
  </joint>
  <!-- flex finger -->
  <link name="left_gripper_finger_1_flex_finger">
    <visual>
      <geometry>
        <mesh filename="./meshes/rg6_v1/visual/flex_finger.stl"/>
      </geometry>
      <material name="onrobot/dark_grey"/>
    </visual>
    <collision>
      <geometry>
        <mesh filename="./meshes/rg6_v1/collision/flex_finger.stl"/>
      </geometry>
    </collision>
    <inertial>
      <mass value="0.001"/>
      <inertia ixx="0.001" ixy="0.0" ixz="0.0" iyy="0.001" iyz="0.0" izz="0.001"/>
    </inertial>
  </link>
  <joint name="left_gripper_finger_1_flex_finger_joint" type="fixed">
    <parent link="left_gripper_finger_1_finger_tip"/>
    <child link="left_gripper_finger_1_flex_finger"/>
    <origin rpy="0.0 0.0 0.0" xyz="0.0098 0.0 0.0218"/>
  </joint>
  <!-- origin frame -->
  <link name="left_gripper_finger_2_origin">
    <inertial>
      <mass value="0.001"/>
      <inertia ixx="0.00001" ixy="0.0" ixz="0.0" iyy="0.00001" iyz="0.0" izz="0.00001"/>
    </inertial>
  </link>
  <joint name="left_gripper_finger_2_origin_joint" type="fixed">
    <parent link="left_gripper_body"/>
    <child link="left_gripper_finger_2_origin"/>
    <origin rpy="0 0 3.141592653589793" xyz="0 0 0"/>
  </joint>
  <!-- moment bar -->
  <link name="left_gripper_finger_2_moment_arm">
    <visual>
      <geometry>
        <mesh filename="./meshes/rg6_v1/visual/moment_arm.stl"/>
      </geometry>
      <material name="onrobot/light_grey"/>
    </visual>
    <collision>
      <geometry>
        <mesh filename="./meshes/rg6_v1/collision/moment_arm.stl"/>
      </geometry>
    </collision>
    <inertial>
      <mass value="0.001"/>
      <inertia ixx="0.001" ixy="0.0" ixz="0.0" iyy="0.001" iyz="0.0" izz="0.001"/>
    </inertial>
  </link>
  <joint name="left_gripper_mirror_joint" type="revolute">
    <parent link="left_gripper_finger_2_origin"/>
    <child link="left_gripper_finger_2_moment_arm"/>
    <axis xyz="0 1 0"/>
    <origin rpy="0.0 -0.49 0.0" xyz="-0.0238 0.0 0.066"/>
    <limit effort="10.0" lower="0.0" upper="1.3" velocity="2.4"/>
    <dynamics damping="0.5"/>
    <mimic joint="left_gripper_joint" multiplier="1" offset="0"/>
  </joint>
  <!-- truss bar -->
  <link name="left_gripper_finger_2_truss_arm">
    <visual>
      <geometry>
        <mesh filename="./meshes/rg6_v1/visual/truss_arm.stl"/>
      </geometry>
      <material name="onrobot/light_grey"/>
    </visual>
    <collision>
      <geometry>
        <mesh filename="./meshes/rg6_v1/collision/truss_arm.stl"/>
      </geometry>
    </collision>
    <inertial>
      <mass value="0.001"/>
      <inertia ixx="0.001" ixy="0.0" ixz="0.0" iyy="0.001" iyz="0.0" izz="0.001"/>
    </inertial>
  </link>
  <joint name="left_gripper_finger_2_truss_arm_joint" type="revolute">
    <parent link="left_gripper_finger_2_origin"/>
    <child link="left_gripper_finger_2_truss_arm"/>
    <axis xyz="0 1 0"/>
    <origin rpy="0.0 -0.49 0.0" xyz="-0.0105 0.0 0.0891"/>
    <limit effort="10.0" lower="0.0" upper="1.3" velocity="2.4"/>
    <mimic joint="left_gripper_joint" multiplier="1" offset="0"/>
  </joint>
  <link name="left_gripper_finger_2_safety_shield">
    <visual>
      <geometry>
        <mesh filename="./meshes/rg6_v1/visual/safety_shield.stl"/>
      </geometry>
      <material name="onrobot/dark_grey"/>
    </visual>
    <collision>
      <geometry>
        <!-- <mesh filename="package://onrobot_description/meshes/${model}/collision/safety_shield.stl"/> -->
        <box size="0.0 0.0 0.0"/>
      </geometry>
    </collision>
    <inertial>
      <mass value="0.001"/>
      <inertia ixx="0.001" ixy="0.0" ixz="0.0" iyy="0.001" iyz="0.0" izz="0.001"/>
    </inertial>
  </link>
  <joint name="left_gripper_finger_2_safety_shield_joint" type="revolute">
    <parent link="left_gripper_finger_2_finger_tip"/>
    <child link="left_gripper_finger_2_safety_shield"/>
    <axis xyz="0 1 0"/>
    <origin rpy="0.0 -0.49 0.0" xyz="-0.00665 0.0 -0.01155"/>
    <limit effort="10.0" lower="0.0" upper="1.3" velocity="2.4"/>
    <mimic joint="left_gripper_joint" multiplier="1" offset="0"/>
  </joint>
  <!-- finger tip -->
  <link name="left_gripper_finger_2_finger_tip">
    <visual>
      <geometry>
        <mesh filename="./meshes/rg6_v1/visual/finger_tip.stl"/>
      </geometry>
      <material name="onrobot/light_grey"/>
    </visual>
    <collision>
      <geometry>
        <mesh filename="./meshes/rg6_v1/collision/finger_tip_1.stl"/>
      </geometry>
    </collision>
    <collision>
      <geometry>
        <mesh filename="./meshes/rg6_v1/collision/finger_tip_2.stl"/>
      </geometry>
    </collision>
    <inertial>
      <mass value="0.001"/>
      <inertia ixx="0.001" ixy="0.0" ixz="0.0" iyy="0.001" iyz="0.0" izz="0.001"/>
    </inertial>
  </link>
  <joint name="left_gripper_finger_2_finger_tip_joint" type="revolute">
    <parent link="left_gripper_finger_2_truss_arm"/>
    <child link="left_gripper_finger_2_finger_tip"/>
    <axis xyz="0 -1 0"/>
    <origin rpy="0.0 0.49 0.0" xyz="-0.05503 0.0 0.05807"/>
    <limit effort="10.0" lower="0.0" upper="1.3" velocity="2.4"/>
    <mimic joint="left_gripper_joint" multiplier="1" offset="0"/>
  </joint>
  <!-- flex finger -->
  <link name="left_gripper_finger_2_flex_finger">
    <visual>
      <geometry>
        <mesh filename="./meshes/rg6_v1/visual/flex_finger.stl"/>
      </geometry>
      <material name="onrobot/dark_grey"/>
    </visual>
    <collision>
      <geometry>
        <mesh filename="./meshes/rg6_v1/collision/flex_finger.stl"/>
      </geometry>
    </collision>
    <inertial>
      <mass value="0.001"/>
      <inertia ixx="0.001" ixy="0.0" ixz="0.0" iyy="0.001" iyz="0.0" izz="0.001"/>
    </inertial>
  </link>
  <joint name="left_gripper_finger_2_flex_finger_joint" type="fixed">
    <parent link="left_gripper_finger_2_finger_tip"/>
    <child link="left_gripper_finger_2_flex_finger"/>
    <origin rpy="0.0 0.0 0.0" xyz="0.0098 0.0 0.0218"/>
  </joint>
  <!-- camera body, with origin at bottom screw mount -->
  <joint name="left_camera_joint" type="fixed">
    <origin rpy="-1.57 -1.57 0.0" xyz="0.0 0.02 0.15"/>
    <parent link="left_tool"/>
    <child link="left_camera_bottom_screw_frame"/>
  </joint>
  <link name="left_camera_bottom_screw_frame"><inertial><mass value="0.001"/><inertia ixx="0.00001" ixy="0" ixz="0" iyy="0.00001" iyz="0" izz="0.00001"/></inertial></link>
  <joint name="left_camera_link_joint" type="fixed">
    <origin rpy="0 0 0" xyz="0.010600000000000002 0.0175 0.0125"/>
    <parent link="left_camera_bottom_screw_frame"/>
    <child link="left_camera_link"/>
  </joint>
  <link name="left_camera_link">
    <visual>
      <!-- the mesh origin is at front plate in between the two infrared camera axes -->
      <origin rpy="1.5707963267948966 0 1.5707963267948966" xyz="0.0043 -0.0175 0"/>
      <geometry>
        <!-- <box size="${d435_cam_width} ${d435_cam_height} ${d435_cam_depth}"/> -->
        <mesh filename="./meshes/realsense2/d435.dae"/>
      </geometry>
      <material name="aluminum"/>
    </visual>
    <collision>
      <origin rpy="0 0 0" xyz="0 -0.0175 0"/>
      <geometry>
        <box size="0.02505 0.09 0.025"/>
      </geometry>
    </collision>
    <inertial>
      <!-- The following are not reliable values, and should not be used for modeling -->
      <mass value="0.072"/>
      <origin xyz="0 0 0"/>
      <inertia ixx="0.003881243" ixy="0.0" ixz="0.0" iyy="0.000498940" iyz="0.0" izz="0.003879257"/>
    </inertial>
  </link>

  <!-- camera depth joints and links -->
  <!-- Check inertial and mass information. Just set to 1e-5 to avoid warnings -->
  <joint name="left_camera_depth_joint" type="fixed">
    <origin xyz="0 0 0" rpy="0 0 0"/>
    <parent link="left_camera_link"/>
    <child link="left_camera_depth_frame" />
  </joint>
  <link name="left_camera_depth_frame"><inertial><mass value="0.001"/><inertia ixx="0.00001" ixy="0" ixz="0" iyy="0.00001" iyz="0" izz="0.00001"/></inertial></link>

  <joint name="left_camera_depth_optical_joint" type="fixed">
    <origin xyz="0 0 0" rpy="-1.5707963267948966 0 -1.5707963267948966" />
    <parent link="left_camera_depth_frame" />
    <child link="left_camera_depth_optical_frame" />
  </joint>
  <link name="left_camera_depth_optical_frame"><inertial><mass value="0.001"/><inertia ixx="0.00001" ixy="0" ixz="0" iyy="0.00001" iyz="0" izz="0.00001"/></inertial></link>

  <!-- camera left IR joints and links -->
  <joint name="left_camera_infra1_joint" type="fixed">
    <origin xyz="0 0 0" rpy="0 0 0" />
    <parent link="left_camera_link" />
    <child link="left_camera_infra1_frame" />
  </joint>
  <link name="left_camera_infra1_frame"><inertial><mass value="0.001"/><inertia ixx="0.00001" ixy="0" ixz="0" iyy="0.00001" iyz="0" izz="0.00001"/></inertial></link>

  <joint name="left_camera_infra1_optical_joint" type="fixed">
    <origin xyz="0 0 0" rpy="-1.5707963267948966 0 -1.5707963267948966" />
    <parent link="left_camera_infra1_frame" />
    <child link="left_camera_infra1_optical_frame" />
  </joint>
  <link name="left_camera_infra1_optical_frame"><inertial><mass value="0.001"/><inertia ixx="0.00001" ixy="0" ixz="0" iyy="0.00001" iyz="0" izz="0.00001"/></inertial></link>

  <!-- camera right IR joints and links -->
  <joint name="left_camera_infra2_joint" type="fixed">
    <origin xyz="0 -0.05 0" rpy="0 0 0" />
    <parent link="left_camera_link" />
    <child link="left_camera_infra2_frame" />
  </joint>
  <link name="left_camera_infra2_frame"><inertial><mass value="0.001"/><inertia ixx="0.00001" ixy="0" ixz="0" iyy="0.00001" iyz="0" izz="0.00001"/></inertial></link>

  <joint name="left_camera_infra2_optical_joint" type="fixed">
    <origin xyz="0 0 0" rpy="-1.5707963267948966 0 -1.5707963267948966" />
    <parent link="left_camera_infra2_frame" />
    <child link="left_camera_infra2_optical_frame" />
  </joint>
  <link name="left_camera_infra2_optical_frame"><inertial><mass value="0.001"/><inertia ixx="0.00001" ixy="0" ixz="0" iyy="0.00001" iyz="0" izz="0.00001"/></inertial></link>

  <!-- camera color joints and links -->
  <joint name="left_camera_color_joint" type="fixed">
    <origin xyz="0 0.015 0" rpy="0 0 0" />
    <parent link="left_camera_link" />
    <child link="left_camera_color_frame" />
  </joint>
  <link name="left_camera_color_frame"><inertial><mass value="0.001"/><inertia ixx="0.00001" ixy="0" ixz="0" iyy="0.00001" iyz="0" izz="0.00001"/></inertial></link>

  <joint name="left_camera_color_optical_joint" type="fixed">
    <origin xyz="0 0 0" rpy="-1.5707963267948966 0 -1.5707963267948966" />
    <parent link="left_camera_color_frame" />
    <child link="left_camera_color_optical_frame" />
  </joint>
  <link name="left_camera_color_optical_frame"><inertial><mass value="0.001"/><inertia ixx="0.00001" ixy="0" ixz="0" iyy="0.00001" iyz="0" izz="0.00001"/></inertial></link>

  <!-- measured from model -->
  <link name="right_base_link">
    <visual>
      <origin rpy="0 0 3.141592653589793" xyz="0 0 0"/>
      <geometry>
        <mesh filename="./meshes/ur5/visual/base.dae"/>
      </geometry>
      <material name="LightGrey">
        <color rgba="0.7 0.7 0.7 1.0"/>
      </material>
    </visual>
    <collision>
      <origin rpy="0 0 3.141592653589793" xyz="0 0 0"/>
      <geometry>
        <mesh filename="./meshes/ur5/collision/base.stl"/>
      </geometry>
    </collision>
    <inertial>
      <mass value="4.0"/>
      <origin rpy="0 0 0" xyz="0.0 0.0 0.0"/>
      <inertia ixx="0.00443333156" ixy="0.0" ixz="0.0" iyy="0.00443333156" iyz="0.0" izz="0.0072"/>
    </inertial>
  </link>
  <joint name="right_shoulder_pan_joint" type="revolute">
    <parent link="right_base_link"/>
    <child link="right_shoulder_link"/>
    <origin rpy="0 0 3.1416620045261725" xyz="0 0 0.08949928559905179"/>
    <axis xyz="0 0 1"/>
    <limit effort="150.0" lower="-3.14159" upper="3.14159" velocity="3.15"/>
    <dynamics damping="0.0" friction="0.0"/>
  </joint>
  <link name="right_shoulder_link">
    <visual>
      <origin rpy="0 0 3.141592653589793" xyz="0 0 0"/>
      <geometry>
        <mesh filename="./meshes/ur5/visual/shoulder.dae"/>
      </geometry>
      <material name="LightGrey">
        <color rgba="0.7 0.7 0.7 1.0"/>
      </material>
    </visual>
    <collision>
      <origin rpy="0 0 3.141592653589793" xyz="0 0 0"/>
      <geometry>
        <mesh filename="./meshes/ur5/collision/shoulder.stl"/>
      </geometry>
    </collision>
    <inertial>
      <mass value="3.7"/>
      <origin rpy="0 0 0" xyz="0.0 0.0 0.0"/>
      <inertia ixx="0.014972352344389999" ixy="0.0" ixz="0.0" iyy="0.014972352344389999" iyz="0.0" izz="0.01040625"/>
    </inertial>
  </link>
  <joint name="right_shoulder_lift_joint" type="revolute">
    <parent link="right_shoulder_link"/>
    <child link="right_upper_arm_link"/>
    <origin rpy="1.569776430478979 0 -1.899595783444728e-05" xyz="-4.453187360131969e-05 0 0"/>
    <axis xyz="0 0 1"/>
    <limit effort="150.0" lower="-3.14159" upper="3.14159" velocity="3.15"/>
    <dynamics damping="0.0" friction="0.0"/>
  </joint>
  <link name="right_upper_arm_link">
    <visual>
      <origin rpy="1.5707963267948966 0 -1.5707963267948966" xyz="0 0 0.136"/>
      <geometry>
        <mesh filename="./meshes/ur5/visual/upperarm.dae"/>
      </geometry>
      <material name="LightGrey">
        <color rgba="0.7 0.7 0.7 1.0"/>
      </material>
    </visual>
    <collision>
      <origin rpy="1.5707963267948966 0 -1.5707963267948966" xyz="0 0 0.136"/>
      <geometry>
        <mesh filename="./meshes/ur5/collision/upperarm.stl"/>
      </geometry>
    </collision>
    <inertial>
      <mass value="8.393"/>
      <origin rpy="0 1.5707963267948966 0" xyz="-0.2127977589367988 0.0 0.136"/>
      <inertia ixx="0.13424006761999863" ixy="0.0" ixz="0.0" iyy="0.13424006761999863" iyz="0.0" izz="0.0151074"/>
    </inertial>
  </link>
  <joint name="right_elbow_joint" type="revolute">
    <parent link="right_upper_arm_link"/>
    <child link="right_forearm_link"/>
    <origin rpy="0.003664895000787752 0.003110587533505237 -1.094175347315775e-05" xyz="-0.4255955178735976 0 0"/>
    <axis xyz="0 0 1"/>
    <limit effort="150.0" lower="-3.14159" upper="3.14159" velocity="3.15"/>
    <dynamics damping="0.0" friction="0.0"/>
  </joint>
  <link name="right_forearm_link">
    <visual>
      <origin rpy="1.5707963267948966 0 -1.5707963267948966" xyz="0 0 0.0165"/>
      <geometry>
        <mesh filename="./meshes/ur5/visual/forearm.dae"/>
      </geometry>
      <material name="LightGrey">
        <color rgba="0.7 0.7 0.7 1.0"/>
      </material>
    </visual>
    <collision>
      <origin rpy="1.5707963267948966 0 -1.5707963267948966" xyz="0 0 0.0165"/>
      <geometry>
        <mesh filename="./meshes/ur5/collision/forearm.stl"/>
      </geometry>
    </collision>
    <inertial>
      <mass value="2.275"/>
      <origin rpy="0 1.5707963267948966 0" xyz="-0.2127977589367988 0.0 0.0165"/>
      <inertia ixx="0.031243742089560593" ixy="0.0" ixz="0.0" iyy="0.031243742089560593" iyz="0.0" izz="0.004095"/>
    </inertial>
  </link>
  <joint name="right_wrist_1_joint" type="revolute">
    <parent link="right_forearm_link"/>
    <child link="right_wrist_1_link"/>
    <origin rpy="0.005347748217401119 0.0006785171055329065 -2.742538745494148e-05" xyz="-0.3924311684839673 -0.0005944496110317049 0.1111578032629135"/>
    <axis xyz="0 0 1"/>
    <limit effort="28.0" lower="-3.14159" upper="3.14159" velocity="3.2"/>
    <dynamics damping="0.0" friction="0.0"/>
  </joint>
  <link name="right_wrist_1_link">
    <visual>
      <origin rpy="1.5707963267948966 0 0" xyz="0 0 -0.093"/>
      <geometry>
        <mesh filename="./meshes/ur5/visual/wrist1.dae"/>
      </geometry>
      <material name="LightGrey">
        <color rgba="0.7 0.7 0.7 1.0"/>
      </material>
    </visual>
    <collision>
      <origin rpy="1.5707963267948966 0 0" xyz="0 0 -0.093"/>
      <geometry>
        <mesh filename="./meshes/ur5/collision/wrist1.stl"/>
      </geometry>
    </collision>
    <inertial>
      <mass value="1.219"/>
      <origin rpy="0 0 0" xyz="0.0 0.0 0.0"/>
      <inertia ixx="0.002629037495458916" ixy="0.0" ixz="0.0" iyy="0.002629037495458916" iyz="0.0" izz="0.0034284375"/>
    </inertial>
  </link>
  <joint name="right_wrist_2_joint" type="revolute">
    <parent link="right_wrist_1_link"/>
    <child link="right_wrist_2_link"/>
    <origin rpy="1.569468403067662 0 -9.542494196330857e-05" xyz="2.941862599780075e-05 -0.09489788806426759 0.0001260172312971319"/>
    <axis xyz="0 0 1"/>
    <limit effort="28.0" lower="-3.14159" upper="3.14159" velocity="3.2"/>
    <dynamics damping="0.0" friction="0.0"/>
  </joint>
  <link name="right_wrist_2_link">
    <visual>
      <origin rpy="0 0 0" xyz="0 0 -0.095"/>
      <geometry>
        <mesh filename="./meshes/ur5/visual/wrist2.dae"/>
      </geometry>
      <material name="LightGrey">
        <color rgba="0.7 0.7 0.7 1.0"/>
      </material>
    </visual>
    <collision>
      <origin rpy="0 0 0" xyz="0 0 -0.095"/>
      <geometry>
        <mesh filename="./meshes/ur5/collision/wrist2.stl"/>
      </geometry>
    </collision>
    <inertial>
      <mass value="1.219"/>
      <origin rpy="0 0 0" xyz="0.0 0.0 0.0"/>
      <inertia ixx="0.0017879874158416194" ixy="0.0" ixz="0.0" iyy="0.0017879874158416194" iyz="0.0" izz="0.0021942"/>
    </inertial>
  </link>
  <joint name="right_wrist_3_joint" type="revolute">
    <parent link="right_wrist_2_link"/>
    <child link="right_wrist_3_link"/>
    <origin rpy="1.572087084765102 3.141592653589793 3.141548784260287" xyz="2.687562318826077e-05 0.0824693622601854 0.0001064480457512508"/>
    <axis xyz="0 0 1"/>
    <limit effort="28.0" lower="-3.14159" upper="3.14159" velocity="3.2"/>
    <dynamics damping="0.0" friction="0.0"/>
  </joint>
  <link name="right_wrist_3_link">
    <visual>
      <origin rpy="1.5707963267948966 0 0" xyz="0 0 -0.0818"/>
      <geometry>
        <mesh filename="./meshes/ur5/visual/wrist3.dae"/>
      </geometry>
      <material name="LightGrey">
        <color rgba="0.7 0.7 0.7 1.0"/>
      </material>
    </visual>
    <collision>
      <origin rpy="1.5707963267948966 0 0" xyz="0 0 -0.0823"/>
      <geometry>
        <mesh filename="./meshes/ur5/collision/wrist3.stl"/>
      </geometry>
    </collision>
    <inertial>
      <mass value="0.1879"/>
      <origin rpy="0 0 0" xyz="0.0 0.0 -0.01525"/>
      <inertia ixx="8.062472608343e-05" ixy="0.0" ixz="0.0" iyy="8.062472608343e-05" iyz="0.0" izz="0.0001321171875"/>
    </inertial>
  </link>
  <joint name="right_ee_fixed_joint" type="fixed">
    <parent link="right_wrist_3_link"/>
    <child link="right_ee_link"/>
    <origin rpy="0.0 -1.5707963267948966 1.5707963267948966" xyz="0.0 0.0 0.0"/>
  </joint>
  <link name="right_ee_link">
    <collision>
      <geometry>
        <box size="0.01 0.01 0.01"/>
      </geometry>
      <origin rpy="0 0 0" xyz="-0.01 0 0"/>
    </collision>
  <inertial><mass value="0.001"/><inertia ixx="0.00001" ixy="0" ixz="0" iyy="0.00001" iyz="0" izz="0.00001"/></inertial></link>
  <joint name="right_wrist_3_passive_joint" type="fixed">
    <origin rpy="0 0 0" xyz="0 0 0"/>
    <parent link="right_wrist_3_link"/>
    <child link="right_tool0"/>
  </joint>
  <!-- ROS base_link to UR 'Base' Coordinates transform -->
  <link name="right_base"><inertial><mass value="0.001"/><inertia ixx="0.00001" ixy="0" ixz="0" iyy="0.00001" iyz="0" izz="0.00001"/></inertial></link>
  <joint name="right_base_link-base_fixed_joint" type="fixed">
    <!-- NOTE: this rotation is only needed as long as base_link itself is
                 not corrected wrt the real robot (ie: rotated over 180
                 degrees)
      -->
    <origin rpy="0 0 -3.141592653589793" xyz="0 0 0"/>
    <parent link="right_base_link"/>
    <child link="right_base"/>
  </joint>
  <!-- Frame coincident with all-zeros TCP on UR controller -->
  <link name="right_tool0"><inertial><mass value="0.001"/><inertia ixx="0.00001" ixy="0" ixz="0" iyy="0.00001" iyz="0" izz="0.00001"/></inertial></link>
  <joint name="right_base_joint" type="fixed">
    <origin rpy="0.0 2.356194490192345 0.0" xyz="0.17906 -0.3825 0.78936"/>
    <parent link="prl_ur5_base"/>
    <child link="right_base_link"/>
  </joint>
  <!-- mount the fts to the robot -->
  <joint name="right_ft300_fix" type="fixed">
    <origin rpy="0 0 -1.5707963267948966" xyz="0 0 -0.004"/>
    <parent link="right_tool0"/>
    <child link="right_ft300_mounting_plate"/>
  </joint>
  <!-- Link representing the FT300 force-torque sensor -->
  <link name="right_ft300_sensor">
    <inertial>
      <origin rpy="0 0 0" xyz="0 0 -0.017"/>
      <mass value="0.300"/>
      <inertia ixx="0.000262" ixy="0" ixz="1e-06" iyx="0" iyy="0.000265" iyz="1e-06" izx="-1e-06" izy="1e-06" izz="0.000219"/>
    </inertial>
    <visual>
      <origin rpy="0 0 0" xyz="0 0 0"/>
      <geometry>
        <mesh filename="./meshes/robotiq_ft_sensor/visual/robotiq_ft300.STL"/>
      </geometry>
      <material name="Robotiq-Black">
        <color rgba="0.2 0.2 0.2 1.0"/>
      </material>
    </visual>
    <collision>
      <origin rpy="0 0 0" xyz="0 0 0"/>
      <geometry>
        <mesh filename="./meshes/robotiq_ft_sensor/collision/robotiq_ft300.STL"/>
      </geometry>
    </collision>
  </link>
  <!-- Link representing the FT300 mounting plate -->
  <link name="right_ft300_mounting_plate">
    <visual>
      <origin rpy="0 0 0" xyz="0 0 0"/>
      <geometry>
        <mesh filename="./meshes/robotiq_ft_sensor/visual/mountings/robotiq_ft300-G-062-COUPLING_G-50-4M6-1D6_20181119.STL"/>
      </geometry>
      <material name="Robotiq-Grey">
        <color rgba="0.4 0.4 0.4 1.0"/>
      </material>
    </visual>
    <collision>
      <origin rpy="0 0 0" xyz="0 0 0"/>
      <geometry>
        <mesh filename="./meshes/robotiq_ft_sensor/collision/mountings/robotiq_ft300-G-062-COUPLING_G-50-4M6-1D6_20181119.STL"/>
      </geometry>
    </collision>
  <inertial><mass value="0.001"/><inertia ixx="0.00001" ixy="0" ixz="0" iyy="0.00001" iyz="0" izz="0.00001"/></inertial></link>
  <!-- Connect force sensor with mounting/coupling plate -->
  <joint name="right_ft300_mounting_plate" type="fixed">
    <origin rpy="0 3.141592653589793 0" xyz="0 0 0.0415"/>
    <parent link="right_ft300_mounting_plate"/>
    <child link="right_ft300_sensor"/>
  </joint>
  <!-- FORCE REFERENCE FRAME _______________________________________________________________________________
            As specified in the documentation:
            - The Z axis passes through the center of the depression with positive direction in the tool direction.
            - The X axis traces a symmetric line centered on the connector; the positive direction
                points the opposite way away from the connector.
            - The Y axis uses the right hand thumb rule according to X-Z. -->
  <joint name="right_measurment_joint" type="fixed">
    <origin rpy="0 3.141592653589793 -1.5707963267948966" xyz="0 0 0"/>
    <parent link="right_ft300_sensor"/>
    <child link="right_robotiq_ft_frame_id"/>
  </joint>
  <link name="right_robotiq_ft_frame_id"><inertial><mass value="0.001"/><inertia ixx="0.00001" ixy="0" ixz="0" iyy="0.00001" iyz="0" izz="0.00001"/></inertial></link>
  <!-- tool frame -->
  <link name="right_tool"><inertial><mass value="0.001"/><inertia ixx="0.00001" ixy="0" ixz="0" iyy="0.00001" iyz="0" izz="0.00001"/></inertial></link>
  <joint name="right_tool_joint" type="fixed">
    <origin rpy="0 0 0" xyz="0 0 0"/>
    <parent link="right_robotiq_ft_frame_id"/>
    <child link="right_tool"/>
  </joint>
  <!-- bracket -->
  <link name="right_gripper_bracket">
    <visual>
      <geometry>
        <mesh filename="./meshes/rg2_v1/visual/single_bracket.stl"/>
      </geometry>
      <material name="onrobot/grey"/>
    </visual>
    <collision>
      <geometry>
        <mesh filename="./meshes/rg2_v1/collision/single_bracket.stl"/>
      </geometry>
    </collision>
    <inertial>
      <mass value="0.09"/>
      <inertia ixx="0.001" ixy="0.0" ixz="0.0" iyy="0.001" iyz="0.0" izz="0.001"/>
    </inertial>
  </link>
  <joint name="right_gripper_bracket_joint" type="fixed">
    <parent link="right_tool"/>
    <child link="right_gripper_bracket"/>
    <origin rpy="0.0 0.0 0.0" xyz="0.0 0.0 0.0"/>
  </joint>
  <!-- body -->
  <link name="right_gripper_body">
    <visual>
      <geometry>
        <mesh filename="./meshes/rg2_v1/visual/body.stl"/>
      </geometry>
      <material name="onrobot/light_grey"/>
    </visual>
    <collision>
      <geometry>
        <mesh filename="./meshes/rg2_v1/collision/body.stl"/>
      </geometry>
    </collision>
    <inertial>
      <mass value="0.65"/>
      <inertia ixx="0.001" ixy="0.0" ixz="0.0" iyy="0.001" iyz="0.0" izz="0.001"/>
    </inertial>
  </link>
  <joint name="right_gripper_body_joint" type="fixed">
    <parent link="right_gripper_bracket"/>
    <child link="right_gripper_body"/>
    <origin rpy="0.0 0.0 0.0" xyz="0.0 0.0 0.05"/>
  </joint>
  <!-- grasp frame -->
  <link name="right_gripper_grasp_frame"><inertial><mass value="0.001"/><inertia ixx="0.00001" ixy="0" ixz="0" iyy="0.00001" iyz="0" izz="0.00001"/></inertial></link>
  <joint name="right_gripper_grasp_frame_joint" type="fixed">
    <parent link="right_gripper_body"/>
    <child link="right_gripper_grasp_frame"/>
    <origin rpy="0.0 0.0 0.0" xyz="0.0 0.0 0.14"/>
  </joint>
  <!-- origin frame -->
  <link name="right_gripper_finger_1_origin">
    <inertial>
      <mass value="0.001"/>
      <inertia ixx="0.00001" ixy="0.0" ixz="0.0" iyy="0.00001" iyz="0.0" izz="0.00001"/>
    </inertial>
  </link>
  <joint name="right_gripper_finger_1_origin_joint" type="fixed">
    <parent link="right_gripper_body"/>
    <child link="right_gripper_finger_1_origin"/>
    <origin rpy="0 0 0" xyz="0 0 0"/>
  </joint>
  <!-- moment bar -->
  <link name="right_gripper_finger_1_moment_arm">
    <visual>
      <geometry>
        <mesh filename="./meshes/rg2_v1/visual/moment_arm.stl"/>
      </geometry>
      <material name="onrobot/light_grey"/>
    </visual>
    <collision>
      <geometry>
        <mesh filename="./meshes/rg2_v1/collision/moment_arm.stl"/>
      </geometry>
    </collision>
    <inertial>
      <mass value="0.001"/>
      <inertia ixx="0.001" ixy="0.0" ixz="0.0" iyy="0.001" iyz="0.0" izz="0.001"/>
    </inertial>
  </link>
  <joint name="right_gripper_joint" type="revolute">
    <parent link="right_gripper_finger_1_origin"/>
    <child link="right_gripper_finger_1_moment_arm"/>
    <axis xyz="0 1 0"/>
    <origin rpy="0.0 -0.772 0.0" xyz="-0.017 0.0 0.055"/>
    <limit effort="2.2" lower="0.0" upper="1.3" velocity="0.5"/>
    <dynamics damping="0.5"/>
  </joint>
  <!-- truss bar -->
  <link name="right_gripper_finger_1_truss_arm">
    <visual>
      <geometry>
        <mesh filename="./meshes/rg2_v1/visual/truss_arm.stl"/>
      </geometry>
      <material name="onrobot/light_grey"/>
    </visual>
    <collision>
      <geometry>
        <mesh filename="./meshes/rg2_v1/collision/truss_arm.stl"/>
      </geometry>
    </collision>
    <inertial>
      <mass value="0.001"/>
      <inertia ixx="0.001" ixy="0.0" ixz="0.0" iyy="0.001" iyz="0.0" izz="0.001"/>
    </inertial>
  </link>
  <joint name="right_gripper_finger_1_truss_arm_joint" type="revolute">
    <parent link="right_gripper_finger_1_origin"/>
    <child link="right_gripper_finger_1_truss_arm"/>
    <axis xyz="0 1 0"/>
    <origin rpy="0.0 -0.772 0.0" xyz="-0.0075 0.0 0.0715"/>
    <limit effort="2.2" lower="0.0" upper="1.3" velocity="0.5"/>
    <mimic joint="right_gripper_joint" multiplier="1" offset="0"/>
  </joint>
  <!-- finger tip -->
  <link name="right_gripper_finger_1_finger_tip">
    <visual>
      <geometry>
        <mesh filename="./meshes/rg2_v1/visual/finger_tip.stl"/>
      </geometry>
      <material name="onrobot/light_grey"/>
    </visual>
    <collision>
      <geometry>
        <mesh filename="./meshes/rg2_v1/collision/finger_tip_1.stl"/>
      </geometry>
    </collision>
    <collision>
      <geometry>
        <mesh filename="./meshes/rg2_v1/collision/finger_tip_2.stl"/>
      </geometry>
    </collision>
    <inertial>
      <mass value="0.001"/>
      <inertia ixx="0.001" ixy="0.0" ixz="0.0" iyy="0.001" iyz="0.0" izz="0.001"/>
    </inertial>
  </link>
  <joint name="right_gripper_finger_1_finger_tip_joint" type="revolute">
    <parent link="right_gripper_finger_1_truss_arm"/>
    <child link="right_gripper_finger_1_finger_tip"/>
    <axis xyz="0 -1 0"/>
    <origin rpy="0.0 0.772 0.0" xyz="-0.0256 0.0 0.04868"/>
    <limit effort="2.2" lower="0.0" upper="1.3" velocity="0.5"/>
    <mimic joint="right_gripper_joint" multiplier="1" offset="0"/>
  </joint>
  <!-- flex finger -->
  <link name="right_gripper_finger_1_flex_finger">
    <visual>
      <geometry>
        <mesh filename="./meshes/rg2_v1/visual/flex_finger.stl"/>
      </geometry>
      <material name="onrobot/dark_grey"/>
    </visual>
    <collision>
      <geometry>
        <mesh filename="./meshes/rg2_v1/collision/flex_finger.stl"/>
      </geometry>
    </collision>
    <inertial>
      <mass value="0.001"/>
      <inertia ixx="0.001" ixy="0.0" ixz="0.0" iyy="0.001" iyz="0.0" izz="0.001"/>
    </inertial>
  </link>
  <joint name="right_gripper_finger_1_flex_finger_joint" type="fixed">
    <parent link="right_gripper_finger_1_finger_tip"/>
    <child link="right_gripper_finger_1_flex_finger"/>
    <origin rpy="0.0 0.0 0.0" xyz="0.03059 0.0 0.0172"/>
  </joint>
  <!-- origin frame -->
  <link name="right_gripper_finger_2_origin">
    <inertial>
      <mass value="0.001"/>
      <inertia ixx="0.00001" ixy="0.0" ixz="0.0" iyy="0.00001" iyz="0.0" izz="0.00001"/>
    </inertial>
  </link>
  <joint name="right_gripper_finger_2_origin_joint" type="fixed">
    <parent link="right_gripper_body"/>
    <child link="right_gripper_finger_2_origin"/>
    <origin rpy="0 0 3.141592653589793" xyz="0 0 0"/>
  </joint>
  <!-- moment bar -->
  <link name="right_gripper_finger_2_moment_arm">
    <visual>
      <geometry>
        <mesh filename="./meshes/rg2_v1/visual/moment_arm.stl"/>
      </geometry>
      <material name="onrobot/light_grey"/>
    </visual>
    <collision>
      <geometry>
        <mesh filename="./meshes/rg2_v1/collision/moment_arm.stl"/>
      </geometry>
    </collision>
    <inertial>
      <mass value="0.001"/>
      <inertia ixx="0.001" ixy="0.0" ixz="0.0" iyy="0.001" iyz="0.0" izz="0.001"/>
    </inertial>
  </link>
  <joint name="right_gripper_mirror_joint" type="revolute">
    <parent link="right_gripper_finger_2_origin"/>
    <child link="right_gripper_finger_2_moment_arm"/>
    <axis xyz="0 1 0"/>
    <origin rpy="0.0 -0.772 0.0" xyz="-0.017 0.0 0.055"/>
    <limit effort="2.2" lower="0.0" upper="1.3" velocity="0.5"/>
    <dynamics damping="0.5"/>
    <mimic joint="right_gripper_joint" multiplier="1" offset="0"/>
  </joint>
  <!-- truss bar -->
  <link name="right_gripper_finger_2_truss_arm">
    <visual>
      <geometry>
        <mesh filename="./meshes/rg2_v1/visual/truss_arm.stl"/>
      </geometry>
      <material name="onrobot/light_grey"/>
    </visual>
    <collision>
      <geometry>
        <mesh filename="./meshes/rg2_v1/collision/truss_arm.stl"/>
      </geometry>
    </collision>
    <inertial>
      <mass value="0.001"/>
      <inertia ixx="0.001" ixy="0.0" ixz="0.0" iyy="0.001" iyz="0.0" izz="0.001"/>
    </inertial>
  </link>
  <joint name="right_gripper_finger_2_truss_arm_joint" type="revolute">
    <parent link="right_gripper_finger_2_origin"/>
    <child link="right_gripper_finger_2_truss_arm"/>
    <axis xyz="0 1 0"/>
    <origin rpy="0.0 -0.772 0.0" xyz="-0.0075 0.0 0.0715"/>
    <limit effort="2.2" lower="0.0" upper="1.3" velocity="0.5"/>
    <mimic joint="right_gripper_joint" multiplier="1" offset="0"/>
  </joint>
  <!-- finger tip -->
  <link name="right_gripper_finger_2_finger_tip">
    <visual>
      <geometry>
        <mesh filename="./meshes/rg2_v1/visual/finger_tip.stl"/>
      </geometry>
      <material name="onrobot/light_grey"/>
    </visual>
    <collision>
      <geometry>
        <mesh filename="./meshes/rg2_v1/collision/finger_tip_1.stl"/>
      </geometry>
    </collision>
    <collision>
      <geometry>
        <mesh filename="./meshes/rg2_v1/collision/finger_tip_2.stl"/>
      </geometry>
    </collision>
    <inertial>
      <mass value="0.001"/>
      <inertia ixx="0.001" ixy="0.0" ixz="0.0" iyy="0.001" iyz="0.0" izz="0.001"/>
    </inertial>
  </link>
  <joint name="right_gripper_finger_2_finger_tip_joint" type="revolute">
    <parent link="right_gripper_finger_2_truss_arm"/>
    <child link="right_gripper_finger_2_finger_tip"/>
    <axis xyz="0 -1 0"/>
    <origin rpy="0.0 0.772 0.0" xyz="-0.0256 0.0 0.04868"/>
    <limit effort="2.2" lower="0.0" upper="1.3" velocity="0.5"/>
    <mimic joint="right_gripper_joint" multiplier="1" offset="0"/>
  </joint>
  <!-- flex finger -->
  <link name="right_gripper_finger_2_flex_finger">
    <visual>
      <geometry>
        <mesh filename="./meshes/rg2_v1/visual/flex_finger.stl"/>
      </geometry>
      <material name="onrobot/dark_grey"/>
    </visual>
    <collision>
      <geometry>
        <mesh filename="./meshes/rg2_v1/collision/flex_finger.stl"/>
      </geometry>
    </collision>
    <inertial>
      <mass value="0.001"/>
      <inertia ixx="0.001" ixy="0.0" ixz="0.0" iyy="0.001" iyz="0.0" izz="0.001"/>
    </inertial>
  </link>
  <joint name="right_gripper_finger_2_flex_finger_joint" type="fixed">
    <parent link="right_gripper_finger_2_finger_tip"/>
    <child link="right_gripper_finger_2_flex_finger"/>
    <origin rpy="0.0 0.0 0.0" xyz="0.03059 0.0 0.0172"/>
  </joint>
  <!-- camera body, with origin at bottom screw mount -->
  <joint name="right_camera_joint" type="fixed">
    <origin rpy="-1.57 -1.57 0.0" xyz="0.0 0.01 0.13"/>
    <parent link="right_tool"/>
    <child link="right_camera_bottom_screw_frame"/>
  </joint>
  <link name="right_camera_bottom_screw_frame"><inertial><mass value="0.001"/><inertia ixx="0.00001" ixy="0" ixz="0" iyy="0.00001" iyz="0" izz="0.00001"/></inertial></link>
  <joint name="right_camera_link_joint" type="fixed">
    <!-- <origin rpy="0 0 0" xyz="0.010600000000000002 0.0175 0.0125"/> -->
    <origin rpy="0 0 0" xyz="0.010600000000000002 0.0175 0.0125"/>
    <parent link="right_camera_bottom_screw_frame"/>
    <child link="right_camera_link"/>
  </joint>
  <link name="right_camera_link">
    <visual>
      <!-- the mesh origin is at front plate in between the two infrared camera axes -->
      <origin rpy="1.5707963267948966 0 1.5707963267948966" xyz="0.0043 -0.0175 0"/>
      <geometry>
        <!-- <box size="${d435_cam_width} ${d435_cam_height} ${d435_cam_depth}"/> -->
        <mesh filename="./meshes/realsense2/d435.dae"/>
      </geometry>
      <material name="aluminum"/>
    </visual>
    <collision>
      <origin rpy="0 0 0" xyz="0 -0.0175 0"/>
      <geometry>
        <box size="0.02505 0.09 0.025"/>
      </geometry>
    </collision>
    <inertial>
      <!-- The following are not reliable values, and should not be used for modeling -->
      <mass value="0.072"/>
      <origin xyz="0 0 0"/>
      <inertia ixx="0.003881243" ixy="0.0" ixz="0.0" iyy="0.000498940" iyz="0.0" izz="0.003879257"/>
    </inertial>
  </link>

  <!-- camera depth joints and links -->
  <!-- Check inertial and mass information. Just set to 1e-5 to avoid warnings -->
  <joint name="right_camera_depth_joint" type="fixed">
    <origin xyz="0 0 0" rpy="0 0 0"/>
    <parent link="right_camera_link"/>
    <child link="right_camera_depth_frame" />
  </joint>
  <link name="right_camera_depth_frame"><inertial><mass value="0.001"/><inertia ixx="0.00001" ixy="0" ixz="0" iyy="0.00001" iyz="0" izz="0.00001"/></inertial></link>

  <joint name="right_camera_depth_optical_joint" type="fixed">
    <origin xyz="0 0 0" rpy="-1.5707963267948966 0 -1.5707963267948966" />
    <parent link="right_camera_depth_frame" />
    <child link="right_camera_depth_optical_frame" />
  </joint>
  <link name="right_camera_depth_optical_frame"><inertial><mass value="0.001"/><inertia ixx="0.00001" ixy="0" ixz="0" iyy="0.00001" iyz="0" izz="0.00001"/></inertial></link>

  <!-- camera left IR joints and links -->
  <joint name="right_camera_infra1_joint" type="fixed">
    <origin xyz="0 0 0" rpy="0 0 0" />
    <parent link="right_camera_link" />
    <child link="right_camera_infra1_frame" />
  </joint>
  <link name="right_camera_infra1_frame"><inertial><mass value="0.001"/><inertia ixx="0.00001" ixy="0" ixz="0" iyy="0.00001" iyz="0" izz="0.00001"/></inertial></link>

  <joint name="right_camera_infra1_optical_joint" type="fixed">
    <origin xyz="0 0 0" rpy="-1.5707963267948966 0 -1.5707963267948966" />
    <parent link="right_camera_infra1_frame" />
    <child link="right_camera_infra1_optical_frame" />
  </joint>
  <link name="right_camera_infra1_optical_frame"><inertial><mass value="0.001"/><inertia ixx="0.00001" ixy="0" ixz="0" iyy="0.00001" iyz="0" izz="0.00001"/></inertial></link>

  <!-- camera right IR joints and links -->
  <joint name="right_camera_infra2_joint" type="fixed">
    <origin xyz="0 -0.05 0" rpy="0 0 0" />
    <parent link="right_camera_link" />
    <child link="right_camera_infra2_frame" />
  </joint>
  <link name="right_camera_infra2_frame"><inertial><mass value="0.001"/><inertia ixx="0.00001" ixy="0" ixz="0" iyy="0.00001" iyz="0" izz="0.00001"/></inertial></link>

  <joint name="right_camera_infra2_optical_joint" type="fixed">
    <origin xyz="0 0 0" rpy="-1.5707963267948966 0 -1.5707963267948966" />
    <parent link="right_camera_infra2_frame" />
    <child link="right_camera_infra2_optical_frame" />
  </joint>
  <link name="right_camera_infra2_optical_frame"><inertial><mass value="0.001"/><inertia ixx="0.00001" ixy="0" ixz="0" iyy="0.00001" iyz="0" izz="0.00001"/></inertial></link>

  <!-- camera color joints and links -->
  <joint name="right_camera_color_joint" type="fixed">
    <origin xyz="0 0.015 0" rpy="0 0 0" />
    <parent link="right_camera_link" />
    <child link="right_camera_color_frame" />
  </joint>
  <link name="right_camera_color_frame"><inertial><mass value="0.001"/><inertia ixx="0.00001" ixy="0" ixz="0" iyy="0.00001" iyz="0" izz="0.00001"/></inertial></link>

  <joint name="right_camera_color_optical_joint" type="fixed">
    <origin xyz="0 0 0" rpy="-1.5707963267948966 0 -1.5707963267948966" />
    <parent link="right_camera_color_frame" />
    <child link="right_camera_color_optical_frame" />
  </joint>
  <link name="right_camera_color_optical_frame"><inertial><mass value="0.001"/><inertia ixx="0.00001" ixy="0" ixz="0" iyy="0.00001" iyz="0" izz="0.00001"/></inertial></link>
</robot>
